<robot name="ArmAgeddon">
<link name="base_link"></link>
<joint name="base_link_to_base" type="fixed">
<parent link="base_link"/>
<child link="base_1" />
<origin rpy="0.0 0 0" xyz="0 0 0"/>
</joint>
<link name="base_1">
<visual>
<origin xyz="0 0 0" rpy="0 -0 0" />
<geometry>
<mesh filename="package://ArmAgeddonRobot/urdf/visual/base.stl"/>
</geometry>
<material name="base_material">
<color rgba="0.0862745 0.317647 0.690196 1.0"/>
</material>
</visual>
<collision>
<origin xyz="0 0 0" rpy="0 -0 0" />
<geometry>
<mesh filename="package://ArmAgeddonRobot/urdf/visual/base.stl"/>
</geometry>
<material name="base_material">
<color rgba="0.0862745 0.317647 0.690196 1.0"/>
</material>
</collision>
<inertial>
<origin xyz="6.97764e-06 -0.000159294 0.0184354" rpy="0 0 0"/>
<mass value="0.743053" />
<inertia ixx="0.00121567" ixy="5.09794e-08"  ixz="8.27916e-08" iyy="0.00120543" iyz="2.10042e-07" izz="0.00223967" />
</inertial>
</link>

<link name="link1_1">
<visual>
<origin xyz="-2.77833e-17 -9.6662e-16 -0.038" rpy="0 -0 5.29517e-49" />
<geometry>
<mesh filename="package://ArmAgeddonRobot/urdf/visual/link1.stl"/>
</geometry>
<material name="link1_material">
<color rgba="0.0862745 0.317647 0.690196 1.0"/>
</material>
</visual>
<collision>
<origin xyz="-2.77833e-17 -9.6662e-16 -0.038" rpy="0 -0 5.29517e-49" />
<geometry>
<mesh filename="package://ArmAgeddonRobot/urdf/visual/link1.stl"/>
</geometry>
<material name="link1_material">
<color rgba="0.0862745 0.317647 0.690196 1.0"/>
</material>
</collision>
<inertial>
<origin xyz="3.25424e-06 0.0116163 0.0784772" rpy="0 0 0"/>
<mass value="3.23343" />
<inertia ixx="0.012074" ixy="-6.59392e-07"  ixz="-1.10925e-06" iyy="0.0112742" iyz="-0.000903121" izz="0.0106461" />
</inertial>
</link>

<link name="link2_1">
<visual>
<origin xyz="5.48191e-16 -0.086 -0.128" rpy="0 -0 6.3463e-48" />
<geometry>
<mesh filename="package://ArmAgeddonRobot/urdf/visual/link2.stl"/>
</geometry>
<material name="link2_material">
<color rgba="0.0862745 0.317647 0.690196 1.0"/>
</material>
</visual>
<collision>
<origin xyz="5.48191e-16 -0.086 -0.128" rpy="0 -0 6.3463e-48" />
<geometry>
<mesh filename="package://ArmAgeddonRobot/urdf/visual/link2.stl"/>
</geometry>
<material name="link2_material">
<color rgba="0.0862745 0.317647 0.690196 1.0"/>
</material>
</collision>
<inertial>
<origin xyz="8.74659e-05 0.0843313 0.250671" rpy="0 0 0"/>
<mass value="9.15549" />
<inertia ixx="0.476755" ixy="8.18037e-06"  ixz="-0.000290943" iyy="0.474774" iyz="-0.0043779" izz="0.0212216" />
</inertial>
</link>

<link name="link3_1">
<visual>
<origin xyz="1.79739e-15 -0.107891 -0.7407" rpy="0 -0 -2.65037e-32" />
<geometry>
<mesh filename="package://ArmAgeddonRobot/urdf/visual/link3.stl"/>
</geometry>
<material name="link3_material">
<color rgba="0.0862745 0.317647 0.690196 1.0"/>
</material>
</visual>
<collision>
<origin xyz="1.79739e-15 -0.107891 -0.7407" rpy="0 -0 -2.65037e-32" />
<geometry>
<mesh filename="package://ArmAgeddonRobot/urdf/visual/link3.stl"/>
</geometry>
<material name="link3_material">
<color rgba="0.0862745 0.317647 0.690196 1.0"/>
</material>
</collision>
<inertial>
<origin xyz="-2.98492e-06 -0.0564701 0.25692" rpy="0 0 0"/>
<mass value="4.89551" />
<inertia ixx="0.209822" ixy="-6.81899e-07"  ixz="1.38429e-06" iyy="0.209443" iyz="-9.75602e-05" izz="0.00633933" />
</inertial>
</link>

<link name="link4_1">
<visual>
<origin xyz="-1.12684e-07 -0.109891 -1.3123" rpy="0 -0 -1.81122e-33" />
<geometry>
<mesh filename="package://ArmAgeddonRobot/urdf/visual/link4.stl"/>
</geometry>
<material name="link4_material">
<color rgba="0.0862745 0.317647 0.690196 1.0"/>
</material>
</visual>
<collision>
<origin xyz="-1.12684e-07 -0.109891 -1.3123" rpy="0 -0 -1.81122e-33" />
<geometry>
<mesh filename="package://ArmAgeddonRobot/urdf/visual/link4.stl"/>
</geometry>
<material name="link4_material">
<color rgba="0.0862745 0.317647 0.690196 1.0"/>
</material>
</collision>
<inertial>
<origin xyz="3.30173e-06 0.0463971 0.00973728" rpy="0 0 0"/>
<mass value="0.766368" />
<inertia ixx="0.00117304" ixy="2.90713e-08"  ixz="7.7511e-08" iyy="0.00108456" iyz="-9.55118e-05" izz="0.000929703" />
</inertial>
</link>

<link name="link5_1">
<visual>
<origin xyz="1.12684e-07 -0.16389 -1.374" rpy="0 -0 8.87983e-34" />
<geometry>
<mesh filename="package://ArmAgeddonRobot/urdf/visual/link5.stl"/>
</geometry>
<material name="link5_material">
<color rgba="0.0862745 0.317647 0.690196 1.0"/>
</material>
</visual>
<collision>
<origin xyz="1.12684e-07 -0.16389 -1.374" rpy="0 -0 8.87983e-34" />
<geometry>
<mesh filename="package://ArmAgeddonRobot/urdf/visual/link5.stl"/>
</geometry>
<material name="link5_material">
<color rgba="0.0862745 0.317647 0.690196 1.0"/>
</material>
</collision>
<inertial>
<origin xyz="-3.78901e-06 0.00973716 0.0463969" rpy="0 0 0"/>
<mass value="0.766376" />
<inertia ixx="0.00117305" ixy="-8.22887e-08"  ixz="-2.56723e-08" iyy="0.000929705" iyz="-9.55128e-05" izz="0.00108455" />
</inertial>
</link>

<link name="flange_1">
<visual>
<origin xyz="1.05754e-14 -0.225591 -1.428" rpy="0 -0 -1.1438e-32" />
<geometry>
<mesh filename="package://ArmAgeddonRobot/urdf/visual/flange.stl"/>
</geometry>
<material name="flange_material">
<color rgba="0.0862745 0.317647 0.690196 1.0"/>
</material>
</visual>
<collision>
<origin xyz="1.05754e-14 -0.225591 -1.428" rpy="0 -0 -1.1438e-32" />
<geometry>
<mesh filename="package://ArmAgeddonRobot/urdf/visual/flange.stl"/>
</geometry>
<material name="flange_material">
<color rgba="0.0862745 0.317647 0.690196 1.0"/>
</material>
</collision>
<inertial>
<origin xyz="-1.34501e-08 0.0130389 -0.000949442" rpy="0 0 0"/>
<mass value="0.167517" />
<inertia ixx="8.61703e-05" ixy="2.35265e-11"  ixz="-2.88273e-11" iyy="0.000157413" iyz="4.97296e-07" izz="9.23217e-05" />
</inertial>
</link>

<link name="welding_torch_1">
<visual>
<origin xyz="-0.014515 -0.0528228 -0.00593515" rpy="0 -0 9.74349e-33" />
<geometry>
<mesh filename="package://ArmAgeddonRobot/urdf/visual/welding_torch.stl"/>
</geometry>
<material name="welding_torch_material">
<color rgba="0.913725 0.647059 0.329412 1.0"/>
</material>
</visual>
<collision>
<origin xyz="-0.014515 -0.0528228 -0.00593515" rpy="0 -0 9.74349e-33" />
<geometry>
<mesh filename="package://ArmAgeddonRobot/urdf/visual/welding_torch.stl"/>
</geometry>
<material name="welding_torch_material">
<color rgba="0.913725 0.647059 0.329412 1.0"/>
</material>
</collision>
<inertial>
<origin xyz="0.000721595 -0.0929779 0.0432126" rpy="0 0 0"/>
<mass value="0.45283" />
<inertia ixx="0.00460676" ixy="1.03841e-05"  ixz="1.02392e-05" iyy="0.0013967" iyz="0.000793739" izz="0.00344251" />
</inertial>
</link>

<link name="cubo_1">
<visual>
<origin xyz="-8.67362e-19 0 -0.09" rpy="-1.79773e-17 -1.55779e-18 7.11059e-19" />
<geometry>
<mesh filename="package://ArmAgeddonRobot/urdf/visual/cubo.stl"/>
</geometry>
<material name="cubo_material">
<color rgba="0 0 1 1.0"/>
</material>
</visual>
<collision>
<origin xyz="-8.67362e-19 0 -0.09" rpy="-1.79773e-17 -1.55779e-18 7.11059e-19" />
<geometry>
<mesh filename="package://ArmAgeddonRobot/urdf/visual/cubo.stl"/>
</geometry>
<material name="cubo_material">
<color rgba="0 0 1 1.0"/>
</material>
</collision>
<inertial>
<origin xyz="-8.87072e-19 3.29299e-18 -0.045" rpy="0 0 0"/>
<mass value="0.766908" />
<inertia ixx="0.00103533" ixy="8.85693e-22"  ixz="1.15933e-21" iyy="0.00103533" iyz="5.71502e-20" izz="0.00103533" />
</inertial>
</link>

<joint name="tcp" type="revolute">
<origin xyz="0.00106366 -0.430726 0.00599082" rpy="0.677166 0.00744708 -3.13561" />
<parent link="welding_torch_1" />
<child link="cubo_1" />
<axis xyz="0 0 1"/>
<limit effort="1" velocity="20" lower="-6.28319" upper="6.28319"/>
<joint_properties friction="0.0"/>
</joint>

<joint name="flange" type="revolute">
<origin xyz="-1.6404e-16 0.024 0" rpy="-1.3561e-16 -0 3.14159" />
<parent link="flange_1" />
<child link="welding_torch_1" />
<axis xyz="0 1 0"/>
<limit effort="1" velocity="20" lower="-6.28319" upper="6.28319"/>
<joint_properties friction="0.0"/>
</joint>

<joint name="motor5" type="revolute">
<origin xyz="1.12684e-07 0.0617002 0.054" rpy="-3.98128e-30 -0 8.17176e-17" />
<parent link="link5_1" />
<child link="flange_1" />
<axis xyz="-8.17176e-17 -1 -1.3561e-16"/>
<limit effort="1" velocity="20" lower="-6.28319" upper="6.28319"/>
<joint_properties friction="0.0"/>
</joint>

<joint name="motor4" type="revolute">
<origin xyz="-1.12684e-07 0.054 0.0617002" rpy="6.09003e-17 -3.8693e-15 -7.58801e-31" />
<parent link="link4_1" />
<child link="link5_1" />
<axis xyz="5.08012e-31 1.3561e-16 -1"/>
<limit effort="1" velocity="20" lower="-6.28319" upper="6.28319"/>
<joint_properties friction="0.0"/>
</joint>

<joint name="motor3" type="revolute">
<origin xyz="-1.77354e-15 0.002 0.5716" rpy="2.95564e-16 1.10934e-31 -7.06063e-15" />
<parent link="link3_1" />
<child link="link4_1" />
<axis xyz="-7.6806e-17 -1 -1.9651e-16"/>
<limit effort="1" velocity="20" lower="-6.28319" upper="6.28319"/>
<joint_properties friction="0.0"/>
</joint>

<joint name="motor2" type="revolute">
<origin xyz="0.000601452 0.0218907 0.612099" rpy="-2.97176e-16 2.79799e-30 7.11115e-15" />
<parent link="link2_1" />
<child link="link3_1" />
<axis xyz="7.04992e-15 1 3.747e-16"/>
<limit effort="1" velocity="20" lower="-6.28319" upper="6.28319"/>
<joint_properties friction="0.0"/>
</joint>

<joint name="motor1" type="revolute">
<origin xyz="-2.94615e-08 0.086 0.090001" rpy="-2.54489e-17 -0 -1.85063e-31" />
<parent link="link1_1" />
<child link="link2_1" />
<axis xyz="-2.41168e-79 -1 -3.83992e-32"/>
<limit effort="1" velocity="20" lower="-6.28319" upper="6.28319"/>
<joint_properties friction="0.0"/>
</joint>

<joint name="base" type="revolute">
<origin xyz="-1.64532e-18 2.03176e-17 0.038" rpy="6.87467e-17 -1.04395e-16 -4.52008e-33" />
<parent link="base_1" />
<child link="link1_1" />
<axis xyz="-6.10973e-17 -2.54489e-17 -1"/>
<limit effort="1" velocity="20" lower="-6.28319" upper="6.28319"/>
<joint_properties friction="0.0"/>
</joint>


</robot>
